<?xml version="1.0"?>
<robot name="Narkin" version="1.0">

   <!--Youbot -->


   <!--Narko -->
    <gazebo>
      <plugin name="base_controller" filename="libgazebo_ros_planar_move.so">
        <commandTopic>cmd_vel</commandTopic>
        <odometryTopic>odom</odometryTopic>
        <odometryFrame>odom</odometryFrame>
        <odometryRate>50.0</odometryRate>
        <robotBaseFrame>base_footprint</robotBaseFrame>
      </plugin>
    </gazebo>

    <link name="base_footprint" />

    <joint name="base_footprint_joint" type="fixed">
      <child link="narko_base_link"/>
      <parent link="base_footprint"/>
    </joint>

    <link name="narko_base_link">
      <inertial>
        <mass value="40.0"/>
        <origin xyz="0 0 0"/>
        <inertia ixx="5.652232699207" ixy="-0.009719934438" ixz="1.293988226423" iyy="5.669473158652" iyz="-0.007379583694" izz="3.683196351726"/>
      </inertial>
      <visual>
        <origin xyz="0 0 0" rpy="0 0 1.571"/>
        <geometry>
          <mesh filename="package://narko_description/meshes/narko/narko.dae" scale="1 1 1"/>
        </geometry>
      </visual>
      <collision>
        <origin xyz="0 0 -0.06" rpy="0 0 0"/>
        <geometry>
           <box size="0.635 0.582 0.2" />
        </geometry>
      </collision>
      <collision>
        <origin xyz="0 0 0.15" rpy="0 0 0"/>
        <geometry>
           <box size="0.635 0.582 0.08" />
        </geometry>
      </collision>
    </link>

    <!--Kinova -->

      <link name="base_link">
        <inertial>
          <origin xyz="-0.000648 -0.000166 0.084487" rpy="0 0 0" />
          <mass value="1.697" />
          <inertia ixx="0.004622" ixy="9E-06" ixz="6E-05" iyy="0.004495" iyz="9E-06" izz="0.002079" />
        </inertial>
        <visual>
          <origin xyz="0 0 0" rpy="0 0 0" />
          <geometry>
            <mesh filename="package://kortex_description/arms/gen3/7dof/meshes/base_link.STL" />
          </geometry>
          <material name="">
            <color rgba="0.75294 0.75294 0.75294 1" />
          </material>
        </visual>
        <collision>
          <origin xyz="0 0 0" rpy="0 0 0" />
          <geometry>
            <mesh filename="package://kortex_description/arms/gen3/7dof/meshes/base_link.STL" />
          </geometry>
        </collision>
    </link>

	  <joint name="Actuator0" type="fixed">
	    <origin xyz="0 0 0.15" rpy="0 0 0" />
	    <parent link="narko_base_link" />
	    <child link="base_link" />
	  </joint>

    <link name="shoulder_link">
      <inertial>
        <origin xyz="-2.3E-05 -0.010364 -0.07336" rpy="0 0 0" />
        <mass value="1.3773" />
        <inertia ixx="0.00457" ixy="1E-06" ixz="2E-06" iyy="0.004831" iyz="0.000448" izz="0.001409" />
      </inertial>
      <visual>
        <origin xyz="0 0 0" rpy="0 0 0" />
        <geometry>
          <mesh filename="package://kortex_description/arms/gen3/7dof/meshes/shoulder_link.STL" />
        </geometry>
        <material name="">
          <color rgba="0.75294 0.75294 0.75294 1" />
        </material>
      </visual>
      <collision>
        <origin xyz="0 0 0" rpy="0 0 0" />
        <geometry>
          <mesh filename="package://kortex_description/arms/gen3/7dof/meshes/shoulder_link.STL" />
        </geometry>
      </collision>
    </link>
    <joint
      name="joint_1"
      type="continuous">
      <origin xyz="0 0 0.15643" rpy="3.1416 2.7629E-18 -4.9305E-36" />
      <parent
        link="base_link" />
      <child
        link="shoulder_link" />
      <axis
        xyz="0 0 1" />
      <limit
        effort="39"
        velocity="1.3963" />
    </joint>
    <link name="half_arm_1_link">
      <inertial>
        <origin xyz="-4.4E-05 -0.09958 -0.013278" rpy="0 0 0" />
        <mass value="1.1636" />
        <inertia ixx="0.011088" ixy="5E-06" ixz="0" iyy="0.001072" iyz="-0.000691" izz="0.011255" />
      </inertial>
      <visual>
        <origin xyz="0 0 0" rpy="0 0 0" />
        <geometry>
          <mesh filename="package://kortex_description/arms/gen3/7dof/meshes/half_arm_1_link.STL" />
        </geometry>
        <material name="">
          <color rgba="0.75294 0.75294 0.75294 1" />
        </material>
      </visual>
      <collision>
        <origin xyz="0 0 0" rpy="0 0 0" />
        <geometry>
          <mesh filename="package://kortex_description/arms/gen3/7dof/meshes/half_arm_1_link.STL" />
        </geometry>
      </collision>
    </link>
    <joint
      name="joint_2"
      type="revolute">
      <origin xyz="0 0.005375 -0.12838" rpy="1.5708 2.1343E-17 -1.1102E-16" />
      <parent
        link="shoulder_link" />
      <child
        link="half_arm_1_link" />
      <axis
        xyz="0 0 1" />
      <limit lower="-2.41" upper="2.41" effort="39" velocity="1.3963" />
    </joint>
    <link name="half_arm_2_link">
      <inertial>
        <origin xyz="-4.4E-05 -0.006641 -0.117892" rpy="0 0 0" />
        <mass value="1.1636" />
        <inertia ixx="0.010932" ixy="0" ixz="-7E-06" iyy="0.011127" iyz="0.000606" izz="0.001043" />
      </inertial>
      <visual>
        <origin xyz="0 0 0" rpy="0 0 0" />
        <geometry>
          <mesh filename="package://kortex_description/arms/gen3/7dof/meshes/half_arm_2_link.STL" />
        </geometry>
        <material name="">
          <color rgba="0.75294 0.75294 0.75294 1" />
        </material>
      </visual>
      <collision>
        <origin xyz="0 0 0" rpy="0 0 0" />
        <geometry>
          <mesh filename="package://kortex_description/arms/gen3/7dof/meshes/half_arm_2_link.STL" />
        </geometry>
      </collision>
    </link>
    <joint
      name="joint_3"
      type="continuous">
      <origin xyz="0 -0.21038 -0.006375" rpy="-1.5708 1.2326E-32 -2.9122E-16" />
      <parent
        link="half_arm_1_link" />
      <child
        link="half_arm_2_link" />
      <axis
        xyz="0 0 1" />
      <limit
        effort="39"
        velocity="1.3963" />
    </joint>
    <link name="forearm_link">
      <inertial>
        <origin xyz="-1.8E-05 -0.075478 -0.015006" rpy="0 0 0" />
        <mass value="0.9302" />
        <inertia ixx="0.008147" ixy="-1E-06" ixz="0" iyy="0.000631" iyz="-0.0005" izz="0.008316" />
      </inertial>
      <visual>
        <origin xyz="0 0 0" rpy="0 0 0" />
        <geometry>
          <mesh filename="package://kortex_description/arms/gen3/7dof/meshes/forearm_link.STL" />
        </geometry>
        <material name="">
          <color rgba="0.75294 0.75294 0.75294 1" />
        </material>
      </visual>
      <collision>
        <origin xyz="0 0 0" rpy="0 0 0" />
        <geometry>
          <mesh filename="package://kortex_description/arms/gen3/7dof/meshes/forearm_link.STL" />
        </geometry>
      </collision>
    </link>
    <joint
      name="joint_4"
      type="revolute">
      <origin xyz="0 0.006375 -0.21038" rpy="1.5708 -6.6954E-17 -1.6653E-16" />
      <parent
        link="half_arm_2_link" />
      <child
        link="forearm_link" />
      <axis
        xyz="0 0 1" />
      <limit lower="-2.66" upper="2.66" effort="39" velocity="1.3963" />
    </joint>
    <link name="spherical_wrist_1_link">
      <inertial>
        <origin xyz="1E-06 -0.009432 -0.063883" rpy="0 0 0" />
        <mass value="0.6781" />
        <inertia ixx="0.001596" ixy="0" ixz="0" iyy="0.001607" iyz="0.000256" izz="0.000399" />
      </inertial>
      <visual>
        <origin xyz="0 0 0" rpy="0 0 0" />
        <geometry>
          <mesh filename="package://kortex_description/arms/gen3/7dof/meshes/spherical_wrist_1_link.STL" />
        </geometry>
        <material name="">
          <color rgba="0.75294 0.75294 0.75294 1" />
        </material>
      </visual>
      <collision>
        <origin xyz="0 0 0" rpy="0 0 0" />
        <geometry>
          <mesh filename="package://kortex_description/arms/gen3/7dof/meshes/spherical_wrist_1_link.STL" />
        </geometry>
      </collision>
    </link>
    <joint
      name="joint_5"
      type="continuous">
      <origin xyz="0 -0.20843 -0.006375" rpy="-1.5708 2.2204E-16 -6.373E-17" />
      <parent
        link="forearm_link" />
      <child
        link="spherical_wrist_1_link" />
      <axis
        xyz="0 0 1" />
      <limit
        effort="9"
        velocity="1.2218" />
    </joint>
    <link name="spherical_wrist_2_link">
      <inertial>
        <origin xyz="1E-06 -0.045483 -0.00965" rpy="0 0 0" />
        <mass value="0.6781" />
        <inertia ixx="0.001641" ixy="0" ixz="0" iyy="0.00041" iyz="-0.000278" izz="0.001641" />
      </inertial>
      <visual>
        <origin xyz="0 0 0" rpy="0 0 0" />
        <geometry>
          <mesh filename="package://kortex_description/arms/gen3/7dof/meshes/spherical_wrist_2_link.STL" />
        </geometry>
        <material name="">
          <color rgba="0.75294 0.75294 0.75294 1" />
        </material>
      </visual>
      <collision>
        <origin xyz="0 0 0" rpy="0 0 0" />
        <geometry>
          <mesh filename="package://kortex_description/arms/gen3/7dof/meshes/spherical_wrist_2_link.STL" />
        </geometry>
      </collision>
    </link>
    <joint
      name="joint_6"
      type="revolute">
      <origin xyz="0 0.00017505 -0.10593" rpy="1.5708 9.2076E-28 -8.2157E-15" />
      <parent
        link="spherical_wrist_1_link" />
      <child
        link="spherical_wrist_2_link" />
      <axis
        xyz="0 0 1" />
      <limit lower="-2.23" upper="2.23" effort="9" velocity="1.2218" />
    </joint>

    <link name="bracelet_link">
      <inertial>
        <origin xyz="-9.3E-05 0.000132 -0.022905" rpy="0 0 0" />
        <mass value="0.364" />
        <inertia ixx="0.000214" ixy="0" ixz="1E-06" iyy="0.000223" iyz="-2E-06" izz="0.00024" />
      </inertial>
      <visual>
        <origin xyz="0 0 0" rpy="0 0 0" />
        <geometry>
          <mesh filename="package://kortex_description/arms/gen3/7dof/meshes/bracelet_no_vision_link.STL" />
        </geometry>
        <material name="">
          <color rgba="0.75294 0.75294 0.75294 1" />
        </material>
      </visual>
      <collision>
        <origin xyz="0 0 0" rpy="0 0 0" />
        <geometry>
          <mesh filename="package://kortex_description/arms/gen3/7dof/meshes/bracelet_no_vision_link.STL" />
        </geometry>
      </collision>
    </link>

    <joint
      name="joint_7"
      type="continuous">
      <origin xyz="0 -0.10593 -0.00017505" rpy="-1.5708 -5.5511E-17 9.6396E-17" />
      <parent
        link="spherical_wrist_2_link" />
      <child
        link="bracelet_link" />
      <axis
        xyz="0 0 1" />
      <limit
        effort="9"
        velocity="1.2218" />
    </joint>
</robot>
